<?xml version="1.0" encoding="UTF-8"?>
<!-- Generated by org.testng.reporters.JUnitReportReporter -->
<testsuite ignored="0" hostname="DESKTOP-2MQORBC" failures="1" tests="8" name="com.app.testngprgm.FailedTest_two" time="0.058" errors="0" timestamp="05 Apr 2025 15:07:04 GMT" skipped="4">
  <testcase classname="com.app.testngprgm.FailedTest_two" name="test1" time="0.008">
    <skipped/>
  </testcase> <!-- test1 -->
  <testcase classname="com.app.testngprgm.FailedTest_two" name="test1" time="0.006">
    <skipped/>
  </testcase> <!-- test1 -->
  <testcase classname="com.app.testngprgm.FailedTest_two" name="pass" time="0.004"/>
  <testcase classname="com.app.testngprgm.FailedTest_two" name="user" time="0.008"/>
  <testcase classname="com.app.testngprgm.FailedTest_two" name="login" time="0.021"/>
  <testcase classname="com.app.testngprgm.FailedTest_two" name="test1" time="0.003">
    <skipped/>
  </testcase> <!-- test1 -->
  <testcase classname="com.app.testngprgm.FailedTest_two" name="test1" time="0.005">
    <failure message="expected [Aiit] but found [Aiite]" type="java.lang.AssertionError">
      <![CDATA[java.lang.AssertionError: expected [Aiit] but found [Aiite]
	at org.testng.Assert.fail(Assert.java:94)
	at org.testng.Assert.failNotEquals(Assert.java:513)
	at org.testng.Assert.assertEqualsImpl(Assert.java:135)
	at org.testng.Assert.assertEquals(Assert.java:116)
	at org.testng.Assert.assertEquals(Assert.java:190)
	at org.testng.Assert.assertEquals(Assert.java:200)
	at com.app.testngprgm.FailedTest_two.test1(FailedTest_two.java:10)
	at java.base/jdk.internal.reflect.DirectMethodHandleAccessor.invoke(DirectMethodHandleAccessor.java:103)
	at java.base/java.lang.reflect.Method.invoke(Method.java:580)
	at org.testng.internal.MethodInvocationHelper.invokeMethod(MethodInvocationHelper.java:104)
	at org.testng.internal.Invoker.invokeMethod(Invoker.java:645)
	at org.testng.internal.Invoker.retryFailed(Invoker.java:998)
	at org.testng.internal.Invoker.invokeTestMethods(Invoker.java:1200)
	at org.testng.internal.TestMethodWorker.invokeTestMethods(TestMethodWorker.java:129)
	at org.testng.internal.TestMethodWorker.run(TestMethodWorker.java:112)
	at org.testng.TestRunner.privateRun(TestRunner.java:756)
	at org.testng.TestRunner.run(TestRunner.java:610)
	at org.testng.SuiteRunner.runTest(SuiteRunner.java:387)
	at org.testng.SuiteRunner.runSequentially(SuiteRunner.java:382)
	at org.testng.SuiteRunner.privateRun(SuiteRunner.java:340)
	at org.testng.SuiteRunner.run(SuiteRunner.java:289)
	at org.testng.SuiteRunnerWorker.runSuite(SuiteRunnerWorker.java:52)
	at org.testng.SuiteRunnerWorker.run(SuiteRunnerWorker.java:86)
	at org.testng.TestNG.runSuitesSequentially(TestNG.java:1293)
	at org.testng.TestNG.runSuitesLocally(TestNG.java:1218)
	at org.testng.TestNG.runSuites(TestNG.java:1133)
	at org.testng.TestNG.run(TestNG.java:1104)
	at org.testng.remote.AbstractRemoteTestNG.run(AbstractRemoteTestNG.java:115)
	at org.testng.remote.RemoteTestNG.initAndRun(RemoteTestNG.java:293)
	at org.testng.remote.RemoteTestNG.main(RemoteTestNG.java:91)
]]>
    </failure>
  </testcase> <!-- test1 -->
  <testcase classname="com.app.testngprgm.FailedTest_two" name="test1" time="0.003">
    <skipped/>
  </testcase> <!-- test1 -->
</testsuite> <!-- com.app.testngprgm.FailedTest_two -->
